<robot name="mrobot" xmlns:xacro="http://ros.org/wiki/xacro">

  <!-- base_footprint -->
  <link name="base_footprint"/>

  <!-- base_link -->
  <link name="base_link">
      <inertial>
          <origin xyz="-1.51807472482668E-05 2.79346181472073E-05 0.0866200775222906" rpy="0 0 0" />
          <mass value="64.7171962068877" />
          <inertia ixx="1.42225890496994" ixy="-0.000392754943773645" ixz="0.0708650035684445"
                   iyy="3.51249641237205" iyz="-0.000160647777377098" izz="4.57970566976989" />
      </inertial>
      <visual>
          <origin xyz="0 0 0" rpy="0 0 0" />
          <geometry>
            <mesh filename="package://mrobot_description/meshes/base_link.STL" />
          </geometry>
          <material name="">
            <color rgba="0.792156862745098 0.819607843137255 0.933333333333333 1" />
          </material>
      </visual>
      <collision>
          <origin xyz="0 0 0" rpy="0 0 0" />
          <geometry>
            <mesh filename="package://mrobot_description/meshes/base_link.STL" />
          </geometry>
      </collision>
  </link>

  <!-- base_footprint -> base_link joint -->
  <joint name="base_footprint_joint" type="fixed">
      <origin xyz="0 0 0" rpy="0 0 0"/>
      <parent link="base_footprint"/>
      <child link="base_link"/>
  </joint>

  <!-- Wheel and joint macro -->
  <xacro:macro name="wheel" params="name inertial_xyz joint_xyz">
      <link name="${name}_wheel">
        <inertial>
            <origin xyz="${inertial_xyz}" rpy="0 0 0" />
            <mass value="0.99202" />
            <inertia ixx="0.0017289" ixy="-1.1999E-19" ixz="2.0419E-19"
                      iyy="0.0030122" iyz="4.5246E-18" izz="0.0017289" />
        </inertial>
        <visual>
            <origin xyz="0 0 0" rpy="0 0 0" />
            <geometry>
                <mesh filename="package://mrobot_description/meshes/${name}_wheel.STL" />
            </geometry>
            <material name="">
                <color rgba="0.79216 0.81961 0.93333 1" />
            </material>
        </visual>
        <collision>
            <origin xyz="0 0 0" rpy="0 0 0" />
            <geometry>
                <mesh filename="package://mrobot_description/meshes/${name}_wheel.STL" />
            </geometry>
        </collision>
      </link>

      <joint name="${name}_wheel_joint" type="continuous">
        <origin xyz="${joint_xyz}" rpy="0 0 0" />
        <parent link="base_link" />
        <child link="${name}_wheel" />
        <axis xyz="0 1 0" />
      </joint>
    </xacro:macro>

  <!-- Create left and right wheel/joint -->
  <xacro:wheel name="right" inertial_xyz="-1.1102E-16 0.026 2.2204E-16" joint_xyz="-0.1621 -0.242 0.066"  />
  <xacro:wheel name="left" inertial_xyz="-1.1102E-16 -0.026 -1.6653E-16" joint_xyz="-0.1621 0.242 0.066" />  

  <!-- Caster wheel and joint macro -->
  <xacro:macro name="caster" params="name inertial_xyz joint_xyz">
    <link name="${name}_caster">
      <inertial>
          <origin xyz="${inertial_xyz}" rpy="0 0 0" />
          <mass value="0.25623" />
          <inertia ixx="0.00017108" ixy="-2.4081E-10" ixz="-5.2581E-12"
                    iyy="0.00016998" iyz="1.9178E-19" izz="0.00027267" />
      </inertial>
      <visual>
          <origin xyz="0 0 0" rpy="0 0 0" />
          <geometry>
              <mesh filename="package://mrobot_description/meshes/${name}_caster.STL" />
          </geometry>
          <material name="">
              <color rgba="0.79216 0.81961 0.93333 1" />
          </material>
      </visual>
      <collision>
          <origin xyz="0 0 0" rpy="0 0 0" />
          <geometry>
              <mesh filename="package://mrobot_description/meshes/${name}_caster.STL" />
          </geometry>
      </collision>
    </link>

    <joint name="base_to_${name}_caster" type="continuous">
      <origin xyz="${joint_xyz}" rpy="0 0 0" />
      <parent link="base_link" />
      <child link="${name}_caster" />
      <axis xyz="0 0 1" />
    </joint>
  </xacro:macro>
  
  <!-- Create 3 caster wheels -->
  <xacro:caster name="left" inertial_xyz="8.9465E-08 -5.5511E-17 0.019764" joint_xyz="0.3504 0.18406 0"/>
  <xacro:caster name="right" inertial_xyz="8.9465E-08 -2.2204E-16 0.019764" joint_xyz="0.35023 -0.18491 0"/>
  <xacro:caster name="back" inertial_xyz="8.9465E-08 0 0.019764" joint_xyz="-0.31668 -0.0019708 0"/>

</robot>